[2025-03-02T08:54:42.261+0000] {local_task_job_runner.py:123} INFO - ::group::Pre task execution logs
[2025-03-02T08:54:42.279+0000] {taskinstance.py:2614} INFO - Dependencies all met for dep_context=non-requeueable deps ti=<TaskInstance: s3_to_redshift_transformed.run_etl_task manual__2025-03-02T08:49:36.746125+00:00 [queued]>
[2025-03-02T08:54:42.287+0000] {taskinstance.py:2614} INFO - Dependencies all met for dep_context=requeueable deps ti=<TaskInstance: s3_to_redshift_transformed.run_etl_task manual__2025-03-02T08:49:36.746125+00:00 [queued]>
[2025-03-02T08:54:42.287+0000] {taskinstance.py:2867} INFO - Starting attempt 2 of 2
[2025-03-02T08:54:42.300+0000] {taskinstance.py:2890} INFO - Executing <Task(PythonOperator): run_etl_task> on 2025-03-02 08:49:36.746125+00:00
[2025-03-02T08:54:42.308+0000] {logging_mixin.py:190} WARNING - /home/***/.local/lib/python3.12/site-packages/***/task/task_runner/standard_task_runner.py:70 DeprecationWarning: This process (pid=4640) is multi-threaded, use of fork() may lead to deadlocks in the child.
[2025-03-02T08:54:42.310+0000] {standard_task_runner.py:72} INFO - Started process 4642 to run task
[2025-03-02T08:54:42.309+0000] {standard_task_runner.py:104} INFO - Running: ['***', 'tasks', 'run', 's3_to_redshift_transformed', 'run_etl_task', 'manual__2025-03-02T08:49:36.746125+00:00', '--job-id', '158', '--raw', '--subdir', 'DAGS_FOLDER/s3_transformation_redshift_dag.py', '--cfg-path', '/tmp/tmpracq3kir']
[2025-03-02T08:54:42.312+0000] {standard_task_runner.py:105} INFO - Job 158: Subtask run_etl_task
[2025-03-02T08:54:42.328+0000] {logging_mixin.py:190} WARNING - /home/***/.local/lib/python3.12/site-packages/***/settings.py:209 DeprecationWarning: The sql_alchemy_conn option in [core] has been moved to the sql_alchemy_conn option in [database] - the old setting has been used, but please update your config.
[2025-03-02T08:54:42.363+0000] {task_command.py:467} INFO - Running <TaskInstance: s3_to_redshift_transformed.run_etl_task manual__2025-03-02T08:49:36.746125+00:00 [running]> on host 22871c84ed32
[2025-03-02T08:54:42.452+0000] {taskinstance.py:3134} INFO - Exporting env vars: AIRFLOW_CTX_DAG_OWNER='***' AIRFLOW_CTX_DAG_ID='s3_to_redshift_transformed' AIRFLOW_CTX_TASK_ID='run_etl_task' AIRFLOW_CTX_EXECUTION_DATE='2025-03-02T08:49:36.746125+00:00' AIRFLOW_CTX_TRY_NUMBER='2' AIRFLOW_CTX_DAG_RUN_ID='manual__2025-03-02T08:49:36.746125+00:00'
[2025-03-02T08:54:42.453+0000] {taskinstance.py:732} INFO - ::endgroup::
[2025-03-02T08:54:44.090+0000] {logging_mixin.py:190} INFO -   event_details.event_type  ...  event_details.timestamp
0                 purchase  ...     2024-10-13T14:00:00Z
1                page_view  ...     2024-10-13T14:10:00Z
2             wishlist_add  ...     2024-10-13T14:20:00Z

[3 rows x 5 columns]
[2025-03-02T08:54:44.091+0000] {taskinstance.py:3313} ERROR - Task failed with exception
Traceback (most recent call last):
  File "/home/airflow/.local/lib/python3.12/site-packages/pandas/core/indexes/base.py", line 3791, in get_loc
    return self._engine.get_loc(casted_key)
           ^^^^^^^^^^^^^^^^^^^^^^^^^^^^^^^^
  File "index.pyx", line 152, in pandas._libs.index.IndexEngine.get_loc
  File "index.pyx", line 181, in pandas._libs.index.IndexEngine.get_loc
  File "pandas/_libs/hashtable_class_helper.pxi", line 7080, in pandas._libs.hashtable.PyObjectHashTable.get_item
  File "pandas/_libs/hashtable_class_helper.pxi", line 7088, in pandas._libs.hashtable.PyObjectHashTable.get_item
KeyError: 'event_details'

The above exception was the direct cause of the following exception:

Traceback (most recent call last):
  File "/home/airflow/.local/lib/python3.12/site-packages/airflow/models/taskinstance.py", line 768, in _execute_task
    result = _execute_callable(context=context, **execute_callable_kwargs)
             ^^^^^^^^^^^^^^^^^^^^^^^^^^^^^^^^^^^^^^^^^^^^^^^^^^^^^^^^^^^^^
  File "/home/airflow/.local/lib/python3.12/site-packages/airflow/models/taskinstance.py", line 734, in _execute_callable
    return ExecutionCallableRunner(
           ^^^^^^^^^^^^^^^^^^^^^^^^
  File "/home/airflow/.local/lib/python3.12/site-packages/airflow/utils/operator_helpers.py", line 252, in run
    return self.func(*args, **kwargs)
           ^^^^^^^^^^^^^^^^^^^^^^^^^^
  File "/home/airflow/.local/lib/python3.12/site-packages/airflow/models/baseoperator.py", line 424, in wrapper
    return func(self, *args, **kwargs)
           ^^^^^^^^^^^^^^^^^^^^^^^^^^^
  File "/home/airflow/.local/lib/python3.12/site-packages/airflow/operators/python.py", line 238, in execute
    return_value = self.execute_callable()
                   ^^^^^^^^^^^^^^^^^^^^^^^
  File "/home/airflow/.local/lib/python3.12/site-packages/airflow/operators/python.py", line 256, in execute_callable
    return runner.run(*self.op_args, **self.op_kwargs)
           ^^^^^^^^^^^^^^^^^^^^^^^^^^^^^^^^^^^^^^^^^^^
  File "/home/airflow/.local/lib/python3.12/site-packages/airflow/utils/operator_helpers.py", line 252, in run
    return self.func(*args, **kwargs)
           ^^^^^^^^^^^^^^^^^^^^^^^^^^
  File "/opt/airflow/dags/scripts/S3_transformation_redshift.py", line 70, in process_and_load_data
    flattened_df = flatten_json(user_events_df)
                   ^^^^^^^^^^^^^^^^^^^^^^^^^^^^
  File "/opt/airflow/dags/scripts/S3_transformation_redshift.py", line 58, in flatten_json
    event = row["event_details"]
            ~~~^^^^^^^^^^^^^^^^^
  File "/home/airflow/.local/lib/python3.12/site-packages/pandas/core/series.py", line 1040, in __getitem__
    return self._get_value(key)
           ^^^^^^^^^^^^^^^^^^^^
  File "/home/airflow/.local/lib/python3.12/site-packages/pandas/core/series.py", line 1156, in _get_value
    loc = self.index.get_loc(label)
          ^^^^^^^^^^^^^^^^^^^^^^^^^
  File "/home/airflow/.local/lib/python3.12/site-packages/pandas/core/indexes/base.py", line 3798, in get_loc
    raise KeyError(key) from err
KeyError: 'event_details'
[2025-03-02T08:54:44.106+0000] {taskinstance.py:1226} INFO - Marking task as FAILED. dag_id=s3_to_redshift_transformed, task_id=run_etl_task, run_id=manual__2025-03-02T08:49:36.746125+00:00, execution_date=20250302T084936, start_date=20250302T085442, end_date=20250302T085444
[2025-03-02T08:54:44.135+0000] {taskinstance.py:341} INFO - ::group::Post task execution logs
[2025-03-02T08:54:44.135+0000] {standard_task_runner.py:124} ERROR - Failed to execute job 158 for task run_etl_task ('event_details'; 4642)
Traceback (most recent call last):
  File "/home/airflow/.local/lib/python3.12/site-packages/pandas/core/indexes/base.py", line 3791, in get_loc
    return self._engine.get_loc(casted_key)
           ^^^^^^^^^^^^^^^^^^^^^^^^^^^^^^^^
  File "index.pyx", line 152, in pandas._libs.index.IndexEngine.get_loc
  File "index.pyx", line 181, in pandas._libs.index.IndexEngine.get_loc
  File "pandas/_libs/hashtable_class_helper.pxi", line 7080, in pandas._libs.hashtable.PyObjectHashTable.get_item
  File "pandas/_libs/hashtable_class_helper.pxi", line 7088, in pandas._libs.hashtable.PyObjectHashTable.get_item
KeyError: 'event_details'

The above exception was the direct cause of the following exception:

Traceback (most recent call last):
  File "/home/airflow/.local/lib/python3.12/site-packages/airflow/task/task_runner/standard_task_runner.py", line 117, in _start_by_fork
    ret = args.func(args, dag=self.dag)
          ^^^^^^^^^^^^^^^^^^^^^^^^^^^^^
  File "/home/airflow/.local/lib/python3.12/site-packages/airflow/cli/cli_config.py", line 49, in command
    return func(*args, **kwargs)
           ^^^^^^^^^^^^^^^^^^^^^
  File "/home/airflow/.local/lib/python3.12/site-packages/airflow/utils/cli.py", line 116, in wrapper
    return f(*args, **kwargs)
           ^^^^^^^^^^^^^^^^^^
  File "/home/airflow/.local/lib/python3.12/site-packages/airflow/cli/commands/task_command.py", line 483, in task_run
    task_return_code = _run_task_by_selected_method(args, _dag, ti)
                       ^^^^^^^^^^^^^^^^^^^^^^^^^^^^^^^^^^^^^^^^^^^^
  File "/home/airflow/.local/lib/python3.12/site-packages/airflow/cli/commands/task_command.py", line 256, in _run_task_by_selected_method
    return _run_raw_task(args, ti)
           ^^^^^^^^^^^^^^^^^^^^^^^
  File "/home/airflow/.local/lib/python3.12/site-packages/airflow/cli/commands/task_command.py", line 341, in _run_raw_task
    return ti._run_raw_task(
           ^^^^^^^^^^^^^^^^^
  File "/home/airflow/.local/lib/python3.12/site-packages/airflow/utils/session.py", line 97, in wrapper
    return func(*args, session=session, **kwargs)
           ^^^^^^^^^^^^^^^^^^^^^^^^^^^^^^^^^^^^^^
  File "/home/airflow/.local/lib/python3.12/site-packages/airflow/models/taskinstance.py", line 3006, in _run_raw_task
    return _run_raw_task(
           ^^^^^^^^^^^^^^
  File "/home/airflow/.local/lib/python3.12/site-packages/airflow/models/taskinstance.py", line 274, in _run_raw_task
    TaskInstance._execute_task_with_callbacks(
  File "/home/airflow/.local/lib/python3.12/site-packages/airflow/models/taskinstance.py", line 3161, in _execute_task_with_callbacks
    result = self._execute_task(context, task_orig)
             ^^^^^^^^^^^^^^^^^^^^^^^^^^^^^^^^^^^^^^
  File "/home/airflow/.local/lib/python3.12/site-packages/airflow/models/taskinstance.py", line 3185, in _execute_task
    return _execute_task(self, context, task_orig)
           ^^^^^^^^^^^^^^^^^^^^^^^^^^^^^^^^^^^^^^^
  File "/home/airflow/.local/lib/python3.12/site-packages/airflow/models/taskinstance.py", line 768, in _execute_task
    result = _execute_callable(context=context, **execute_callable_kwargs)
             ^^^^^^^^^^^^^^^^^^^^^^^^^^^^^^^^^^^^^^^^^^^^^^^^^^^^^^^^^^^^^
  File "/home/airflow/.local/lib/python3.12/site-packages/airflow/models/taskinstance.py", line 734, in _execute_callable
    return ExecutionCallableRunner(
           ^^^^^^^^^^^^^^^^^^^^^^^^
  File "/home/airflow/.local/lib/python3.12/site-packages/airflow/utils/operator_helpers.py", line 252, in run
    return self.func(*args, **kwargs)
           ^^^^^^^^^^^^^^^^^^^^^^^^^^
  File "/home/airflow/.local/lib/python3.12/site-packages/airflow/models/baseoperator.py", line 424, in wrapper
    return func(self, *args, **kwargs)
           ^^^^^^^^^^^^^^^^^^^^^^^^^^^
  File "/home/airflow/.local/lib/python3.12/site-packages/airflow/operators/python.py", line 238, in execute
    return_value = self.execute_callable()
                   ^^^^^^^^^^^^^^^^^^^^^^^
  File "/home/airflow/.local/lib/python3.12/site-packages/airflow/operators/python.py", line 256, in execute_callable
    return runner.run(*self.op_args, **self.op_kwargs)
           ^^^^^^^^^^^^^^^^^^^^^^^^^^^^^^^^^^^^^^^^^^^
  File "/home/airflow/.local/lib/python3.12/site-packages/airflow/utils/operator_helpers.py", line 252, in run
    return self.func(*args, **kwargs)
           ^^^^^^^^^^^^^^^^^^^^^^^^^^
  File "/opt/airflow/dags/scripts/S3_transformation_redshift.py", line 70, in process_and_load_data
    flattened_df = flatten_json(user_events_df)
                   ^^^^^^^^^^^^^^^^^^^^^^^^^^^^
  File "/opt/airflow/dags/scripts/S3_transformation_redshift.py", line 58, in flatten_json
    event = row["event_details"]
            ~~~^^^^^^^^^^^^^^^^^
  File "/home/airflow/.local/lib/python3.12/site-packages/pandas/core/series.py", line 1040, in __getitem__
    return self._get_value(key)
           ^^^^^^^^^^^^^^^^^^^^
  File "/home/airflow/.local/lib/python3.12/site-packages/pandas/core/series.py", line 1156, in _get_value
    loc = self.index.get_loc(label)
          ^^^^^^^^^^^^^^^^^^^^^^^^^
  File "/home/airflow/.local/lib/python3.12/site-packages/pandas/core/indexes/base.py", line 3798, in get_loc
    raise KeyError(key) from err
KeyError: 'event_details'
[2025-03-02T08:54:44.175+0000] {local_task_job_runner.py:266} INFO - Task exited with return code 1
[2025-03-02T08:54:44.194+0000] {taskinstance.py:3901} INFO - 0 downstream tasks scheduled from follow-on schedule check
[2025-03-02T08:54:44.196+0000] {local_task_job_runner.py:245} INFO - ::endgroup::
