[2025-03-03T02:53:29.506+0000] {local_task_job_runner.py:123} INFO - ::group::Pre task execution logs
[2025-03-03T02:53:29.524+0000] {taskinstance.py:2614} INFO - Dependencies all met for dep_context=non-requeueable deps ti=<TaskInstance: s3_data_transformation.transform_s3_data scheduled__2025-03-02T00:00:00+00:00 [queued]>
[2025-03-03T02:53:29.532+0000] {taskinstance.py:2614} INFO - Dependencies all met for dep_context=requeueable deps ti=<TaskInstance: s3_data_transformation.transform_s3_data scheduled__2025-03-02T00:00:00+00:00 [queued]>
[2025-03-03T02:53:29.533+0000] {taskinstance.py:2867} INFO - Starting attempt 2 of 2
[2025-03-03T02:53:29.544+0000] {taskinstance.py:2890} INFO - Executing <Task(PythonOperator): transform_s3_data> on 2025-03-02 00:00:00+00:00
[2025-03-03T02:53:29.550+0000] {logging_mixin.py:190} WARNING - /home/***/.local/lib/python3.12/site-packages/***/task/task_runner/standard_task_runner.py:70 DeprecationWarning: This process (pid=513) is multi-threaded, use of fork() may lead to deadlocks in the child.
[2025-03-03T02:53:29.551+0000] {standard_task_runner.py:72} INFO - Started process 514 to run task
[2025-03-03T02:53:29.550+0000] {standard_task_runner.py:104} INFO - Running: ['***', 'tasks', 'run', 's3_data_transformation', 'transform_s3_data', 'scheduled__2025-03-02T00:00:00+00:00', '--job-id', '196', '--raw', '--subdir', 'DAGS_FOLDER/test/transformation_dag.py', '--cfg-path', '/tmp/tmpbmdysyei']
[2025-03-03T02:53:29.552+0000] {standard_task_runner.py:105} INFO - Job 196: Subtask transform_s3_data
[2025-03-03T02:53:29.567+0000] {logging_mixin.py:190} WARNING - /home/***/.local/lib/python3.12/site-packages/***/settings.py:209 DeprecationWarning: The sql_alchemy_conn option in [core] has been moved to the sql_alchemy_conn option in [database] - the old setting has been used, but please update your config.
[2025-03-03T02:53:29.603+0000] {task_command.py:467} INFO - Running <TaskInstance: s3_data_transformation.transform_s3_data scheduled__2025-03-02T00:00:00+00:00 [running]> on host 22871c84ed32
[2025-03-03T02:53:29.605+0000] {logging_mixin.py:190} WARNING - /home/***/.local/lib/python3.12/site-packages/***/settings.py:470 DeprecationWarning: The sql_alchemy_conn option in [core] has been moved to the sql_alchemy_conn option in [database] - the old setting has been used, but please update your config.
[2025-03-03T02:53:29.699+0000] {taskinstance.py:3134} INFO - Exporting env vars: AIRFLOW_CTX_DAG_OWNER='***' AIRFLOW_CTX_DAG_ID='s3_data_transformation' AIRFLOW_CTX_TASK_ID='transform_s3_data' AIRFLOW_CTX_EXECUTION_DATE='2025-03-02T00:00:00+00:00' AIRFLOW_CTX_TRY_NUMBER='2' AIRFLOW_CTX_DAG_RUN_ID='scheduled__2025-03-02T00:00:00+00:00'
[2025-03-03T02:53:29.700+0000] {taskinstance.py:732} INFO - ::endgroup::
[2025-03-03T02:53:29.742+0000] {taskinstance.py:3313} ERROR - Task failed with exception
Traceback (most recent call last):
  File "/home/airflow/.local/lib/python3.12/site-packages/airflow/models/taskinstance.py", line 768, in _execute_task
    result = _execute_callable(context=context, **execute_callable_kwargs)
             ^^^^^^^^^^^^^^^^^^^^^^^^^^^^^^^^^^^^^^^^^^^^^^^^^^^^^^^^^^^^^
  File "/home/airflow/.local/lib/python3.12/site-packages/airflow/models/taskinstance.py", line 734, in _execute_callable
    return ExecutionCallableRunner(
           ^^^^^^^^^^^^^^^^^^^^^^^^
  File "/home/airflow/.local/lib/python3.12/site-packages/airflow/utils/operator_helpers.py", line 252, in run
    return self.func(*args, **kwargs)
           ^^^^^^^^^^^^^^^^^^^^^^^^^^
  File "/home/airflow/.local/lib/python3.12/site-packages/airflow/models/baseoperator.py", line 424, in wrapper
    return func(self, *args, **kwargs)
           ^^^^^^^^^^^^^^^^^^^^^^^^^^^
  File "/home/airflow/.local/lib/python3.12/site-packages/airflow/operators/python.py", line 238, in execute
    return_value = self.execute_callable()
                   ^^^^^^^^^^^^^^^^^^^^^^^
  File "/home/airflow/.local/lib/python3.12/site-packages/airflow/operators/python.py", line 256, in execute_callable
    return runner.run(*self.op_args, **self.op_kwargs)
           ^^^^^^^^^^^^^^^^^^^^^^^^^^^^^^^^^^^^^^^^^^^
  File "/home/airflow/.local/lib/python3.12/site-packages/airflow/utils/operator_helpers.py", line 252, in run
    return self.func(*args, **kwargs)
           ^^^^^^^^^^^^^^^^^^^^^^^^^^
  File "/opt/airflow/dags/test/transformation_dag.py", line 15, in run_processing_script
    subprocess.run(["python3", "/opt/airflow/dags/scripts/transformation.py"], check=True)
  File "/usr/local/lib/python3.12/subprocess.py", line 573, in run
    raise CalledProcessError(retcode, process.args,
subprocess.CalledProcessError: Command '['python3', '/opt/airflow/dags/scripts/transformation.py']' returned non-zero exit status 2.
[2025-03-03T02:53:29.752+0000] {taskinstance.py:1226} INFO - Marking task as FAILED. dag_id=s3_data_transformation, task_id=transform_s3_data, run_id=scheduled__2025-03-02T00:00:00+00:00, execution_date=20250302T000000, start_date=20250303T025329, end_date=20250303T025329
[2025-03-03T02:53:29.775+0000] {taskinstance.py:341} INFO - ::group::Post task execution logs
[2025-03-03T02:53:29.776+0000] {standard_task_runner.py:124} ERROR - Failed to execute job 196 for task transform_s3_data (Command '['python3', '/opt/airflow/dags/scripts/transformation.py']' returned non-zero exit status 2.; 514)
Traceback (most recent call last):
  File "/home/airflow/.local/lib/python3.12/site-packages/airflow/task/task_runner/standard_task_runner.py", line 117, in _start_by_fork
    ret = args.func(args, dag=self.dag)
          ^^^^^^^^^^^^^^^^^^^^^^^^^^^^^
  File "/home/airflow/.local/lib/python3.12/site-packages/airflow/cli/cli_config.py", line 49, in command
    return func(*args, **kwargs)
           ^^^^^^^^^^^^^^^^^^^^^
  File "/home/airflow/.local/lib/python3.12/site-packages/airflow/utils/cli.py", line 116, in wrapper
    return f(*args, **kwargs)
           ^^^^^^^^^^^^^^^^^^
  File "/home/airflow/.local/lib/python3.12/site-packages/airflow/cli/commands/task_command.py", line 483, in task_run
    task_return_code = _run_task_by_selected_method(args, _dag, ti)
                       ^^^^^^^^^^^^^^^^^^^^^^^^^^^^^^^^^^^^^^^^^^^^
  File "/home/airflow/.local/lib/python3.12/site-packages/airflow/cli/commands/task_command.py", line 256, in _run_task_by_selected_method
    return _run_raw_task(args, ti)
           ^^^^^^^^^^^^^^^^^^^^^^^
  File "/home/airflow/.local/lib/python3.12/site-packages/airflow/cli/commands/task_command.py", line 341, in _run_raw_task
    return ti._run_raw_task(
           ^^^^^^^^^^^^^^^^^
  File "/home/airflow/.local/lib/python3.12/site-packages/airflow/utils/session.py", line 97, in wrapper
    return func(*args, session=session, **kwargs)
           ^^^^^^^^^^^^^^^^^^^^^^^^^^^^^^^^^^^^^^
  File "/home/airflow/.local/lib/python3.12/site-packages/airflow/models/taskinstance.py", line 3006, in _run_raw_task
    return _run_raw_task(
           ^^^^^^^^^^^^^^
  File "/home/airflow/.local/lib/python3.12/site-packages/airflow/models/taskinstance.py", line 274, in _run_raw_task
    TaskInstance._execute_task_with_callbacks(
  File "/home/airflow/.local/lib/python3.12/site-packages/airflow/models/taskinstance.py", line 3161, in _execute_task_with_callbacks
    result = self._execute_task(context, task_orig)
             ^^^^^^^^^^^^^^^^^^^^^^^^^^^^^^^^^^^^^^
  File "/home/airflow/.local/lib/python3.12/site-packages/airflow/models/taskinstance.py", line 3185, in _execute_task
    return _execute_task(self, context, task_orig)
           ^^^^^^^^^^^^^^^^^^^^^^^^^^^^^^^^^^^^^^^
  File "/home/airflow/.local/lib/python3.12/site-packages/airflow/models/taskinstance.py", line 768, in _execute_task
    result = _execute_callable(context=context, **execute_callable_kwargs)
             ^^^^^^^^^^^^^^^^^^^^^^^^^^^^^^^^^^^^^^^^^^^^^^^^^^^^^^^^^^^^^
  File "/home/airflow/.local/lib/python3.12/site-packages/airflow/models/taskinstance.py", line 734, in _execute_callable
    return ExecutionCallableRunner(
           ^^^^^^^^^^^^^^^^^^^^^^^^
  File "/home/airflow/.local/lib/python3.12/site-packages/airflow/utils/operator_helpers.py", line 252, in run
    return self.func(*args, **kwargs)
           ^^^^^^^^^^^^^^^^^^^^^^^^^^
  File "/home/airflow/.local/lib/python3.12/site-packages/airflow/models/baseoperator.py", line 424, in wrapper
    return func(self, *args, **kwargs)
           ^^^^^^^^^^^^^^^^^^^^^^^^^^^
  File "/home/airflow/.local/lib/python3.12/site-packages/airflow/operators/python.py", line 238, in execute
    return_value = self.execute_callable()
                   ^^^^^^^^^^^^^^^^^^^^^^^
  File "/home/airflow/.local/lib/python3.12/site-packages/airflow/operators/python.py", line 256, in execute_callable
    return runner.run(*self.op_args, **self.op_kwargs)
           ^^^^^^^^^^^^^^^^^^^^^^^^^^^^^^^^^^^^^^^^^^^
  File "/home/airflow/.local/lib/python3.12/site-packages/airflow/utils/operator_helpers.py", line 252, in run
    return self.func(*args, **kwargs)
           ^^^^^^^^^^^^^^^^^^^^^^^^^^
  File "/opt/airflow/dags/test/transformation_dag.py", line 15, in run_processing_script
    subprocess.run(["python3", "/opt/airflow/dags/scripts/transformation.py"], check=True)
  File "/usr/local/lib/python3.12/subprocess.py", line 573, in run
    raise CalledProcessError(retcode, process.args,
subprocess.CalledProcessError: Command '['python3', '/opt/airflow/dags/scripts/transformation.py']' returned non-zero exit status 2.
[2025-03-03T02:53:29.816+0000] {local_task_job_runner.py:266} INFO - Task exited with return code 1
[2025-03-03T02:53:29.836+0000] {taskinstance.py:3901} INFO - 0 downstream tasks scheduled from follow-on schedule check
[2025-03-03T02:53:29.839+0000] {local_task_job_runner.py:245} INFO - ::endgroup::
