[2025-03-01T15:21:11.262+0000] {local_task_job_runner.py:123} INFO - ::group::Pre task execution logs
[2025-03-01T15:21:11.284+0000] {taskinstance.py:2614} INFO - Dependencies all met for dep_context=non-requeueable deps ti=<TaskInstance: s3_to_redshift_transformed.run_etl_task manual__2025-03-01T15:15:50.905282+00:00 [queued]>
[2025-03-01T15:21:11.296+0000] {taskinstance.py:2614} INFO - Dependencies all met for dep_context=requeueable deps ti=<TaskInstance: s3_to_redshift_transformed.run_etl_task manual__2025-03-01T15:15:50.905282+00:00 [queued]>
[2025-03-01T15:21:11.297+0000] {taskinstance.py:2867} INFO - Starting attempt 2 of 2
[2025-03-01T15:21:11.312+0000] {taskinstance.py:2890} INFO - Executing <Task(PythonOperator): run_etl_task> on 2025-03-01 15:15:50.905282+00:00
[2025-03-01T15:21:11.322+0000] {logging_mixin.py:190} WARNING - /home/***/.local/lib/python3.12/site-packages/***/task/task_runner/standard_task_runner.py:70 DeprecationWarning: This process (pid=2246) is multi-threaded, use of fork() may lead to deadlocks in the child.
[2025-03-01T15:21:11.323+0000] {standard_task_runner.py:72} INFO - Started process 2262 to run task
[2025-03-01T15:21:11.322+0000] {standard_task_runner.py:104} INFO - Running: ['***', 'tasks', 'run', 's3_to_redshift_transformed', 'run_etl_task', 'manual__2025-03-01T15:15:50.905282+00:00', '--job-id', '110', '--raw', '--subdir', 'DAGS_FOLDER/s3_transformation_redshift_dag.py', '--cfg-path', '/tmp/tmp8l5q45na']
[2025-03-01T15:21:11.325+0000] {standard_task_runner.py:105} INFO - Job 110: Subtask run_etl_task
[2025-03-01T15:21:11.344+0000] {logging_mixin.py:190} WARNING - /home/***/.local/lib/python3.12/site-packages/***/settings.py:209 DeprecationWarning: The sql_alchemy_conn option in [core] has been moved to the sql_alchemy_conn option in [database] - the old setting has been used, but please update your config.
[2025-03-01T15:21:11.387+0000] {task_command.py:467} INFO - Running <TaskInstance: s3_to_redshift_transformed.run_etl_task manual__2025-03-01T15:15:50.905282+00:00 [running]> on host 763fac820cd7
[2025-03-01T15:21:11.504+0000] {taskinstance.py:3134} INFO - Exporting env vars: AIRFLOW_CTX_DAG_OWNER='***' AIRFLOW_CTX_DAG_ID='s3_to_redshift_transformed' AIRFLOW_CTX_TASK_ID='run_etl_task' AIRFLOW_CTX_EXECUTION_DATE='2025-03-01T15:15:50.905282+00:00' AIRFLOW_CTX_TRY_NUMBER='2' AIRFLOW_CTX_DAG_RUN_ID='manual__2025-03-01T15:15:50.905282+00:00'
[2025-03-01T15:21:11.506+0000] {taskinstance.py:732} INFO - ::endgroup::
[2025-03-01T15:21:15.082+0000] {logging_mixin.py:190} INFO - Processed data uploaded to s3://dataingestionjson/processed/2025-02-28/transformed_data.parquet
[2025-03-01T15:21:18.075+0000] {taskinstance.py:3313} ERROR - Task failed with exception
Traceback (most recent call last):
  File "/home/airflow/.local/lib/python3.12/site-packages/airflow/models/taskinstance.py", line 768, in _execute_task
    result = _execute_callable(context=context, **execute_callable_kwargs)
             ^^^^^^^^^^^^^^^^^^^^^^^^^^^^^^^^^^^^^^^^^^^^^^^^^^^^^^^^^^^^^
  File "/home/airflow/.local/lib/python3.12/site-packages/airflow/models/taskinstance.py", line 734, in _execute_callable
    return ExecutionCallableRunner(
           ^^^^^^^^^^^^^^^^^^^^^^^^
  File "/home/airflow/.local/lib/python3.12/site-packages/airflow/utils/operator_helpers.py", line 252, in run
    return self.func(*args, **kwargs)
           ^^^^^^^^^^^^^^^^^^^^^^^^^^
  File "/home/airflow/.local/lib/python3.12/site-packages/airflow/models/baseoperator.py", line 424, in wrapper
    return func(self, *args, **kwargs)
           ^^^^^^^^^^^^^^^^^^^^^^^^^^^
  File "/home/airflow/.local/lib/python3.12/site-packages/airflow/operators/python.py", line 238, in execute
    return_value = self.execute_callable()
                   ^^^^^^^^^^^^^^^^^^^^^^^
  File "/home/airflow/.local/lib/python3.12/site-packages/airflow/operators/python.py", line 256, in execute_callable
    return runner.run(*self.op_args, **self.op_kwargs)
           ^^^^^^^^^^^^^^^^^^^^^^^^^^^^^^^^^^^^^^^^^^^
  File "/home/airflow/.local/lib/python3.12/site-packages/airflow/utils/operator_helpers.py", line 252, in run
    return self.func(*args, **kwargs)
           ^^^^^^^^^^^^^^^^^^^^^^^^^^
  File "/opt/airflow/dags/scripts/S3_transformation_redshift.py", line 104, in process_and_load_data
    cursor.execute(copy_query)
psycopg2.errors.InternalError_: Spectrum Scan Error
DETAIL:  
  -----------------------------------------------
  error:  Spectrum Scan Error
  code:      15007
  context:   Unmatched number of columns between table and file. Table columns: 13, Data columns: 12, File name: https://s3.us-east-1.amazonaws.com/dataingestionjson/processed/2025-02-28/transformed_data.parquet
  query:     21826
  location:  dory_util.cpp:1758
  process:   worker_thread [pid=25433]
  -----------------------------------------------


[2025-03-01T15:21:18.088+0000] {taskinstance.py:1226} INFO - Marking task as FAILED. dag_id=s3_to_redshift_transformed, task_id=run_etl_task, run_id=manual__2025-03-01T15:15:50.905282+00:00, execution_date=20250301T151550, start_date=20250301T152111, end_date=20250301T152118
[2025-03-01T15:21:18.117+0000] {taskinstance.py:341} INFO - ::group::Post task execution logs
[2025-03-01T15:21:18.117+0000] {standard_task_runner.py:124} ERROR - Failed to execute job 110 for task run_etl_task (Spectrum Scan Error
DETAIL:  
  -----------------------------------------------
  error:  Spectrum Scan Error
  code:      15007
  context:   Unmatched number of columns between table and file. Table columns: 13, Data columns: 12, File name: https://s3.us-east-1.amazonaws.com/dataingestionjson/processed/2025-02-28/transformed_data.parquet
  query:     21826
  location:  dory_util.cpp:1758
  process:   worker_thread [pid=25433]
  -----------------------------------------------

; 2262)
Traceback (most recent call last):
  File "/home/airflow/.local/lib/python3.12/site-packages/airflow/task/task_runner/standard_task_runner.py", line 117, in _start_by_fork
    ret = args.func(args, dag=self.dag)
          ^^^^^^^^^^^^^^^^^^^^^^^^^^^^^
  File "/home/airflow/.local/lib/python3.12/site-packages/airflow/cli/cli_config.py", line 49, in command
    return func(*args, **kwargs)
           ^^^^^^^^^^^^^^^^^^^^^
  File "/home/airflow/.local/lib/python3.12/site-packages/airflow/utils/cli.py", line 116, in wrapper
    return f(*args, **kwargs)
           ^^^^^^^^^^^^^^^^^^
  File "/home/airflow/.local/lib/python3.12/site-packages/airflow/cli/commands/task_command.py", line 483, in task_run
    task_return_code = _run_task_by_selected_method(args, _dag, ti)
                       ^^^^^^^^^^^^^^^^^^^^^^^^^^^^^^^^^^^^^^^^^^^^
  File "/home/airflow/.local/lib/python3.12/site-packages/airflow/cli/commands/task_command.py", line 256, in _run_task_by_selected_method
    return _run_raw_task(args, ti)
           ^^^^^^^^^^^^^^^^^^^^^^^
  File "/home/airflow/.local/lib/python3.12/site-packages/airflow/cli/commands/task_command.py", line 341, in _run_raw_task
    return ti._run_raw_task(
           ^^^^^^^^^^^^^^^^^
  File "/home/airflow/.local/lib/python3.12/site-packages/airflow/utils/session.py", line 97, in wrapper
    return func(*args, session=session, **kwargs)
           ^^^^^^^^^^^^^^^^^^^^^^^^^^^^^^^^^^^^^^
  File "/home/airflow/.local/lib/python3.12/site-packages/airflow/models/taskinstance.py", line 3006, in _run_raw_task
    return _run_raw_task(
           ^^^^^^^^^^^^^^
  File "/home/airflow/.local/lib/python3.12/site-packages/airflow/models/taskinstance.py", line 274, in _run_raw_task
    TaskInstance._execute_task_with_callbacks(
  File "/home/airflow/.local/lib/python3.12/site-packages/airflow/models/taskinstance.py", line 3161, in _execute_task_with_callbacks
    result = self._execute_task(context, task_orig)
             ^^^^^^^^^^^^^^^^^^^^^^^^^^^^^^^^^^^^^^
  File "/home/airflow/.local/lib/python3.12/site-packages/airflow/models/taskinstance.py", line 3185, in _execute_task
    return _execute_task(self, context, task_orig)
           ^^^^^^^^^^^^^^^^^^^^^^^^^^^^^^^^^^^^^^^
  File "/home/airflow/.local/lib/python3.12/site-packages/airflow/models/taskinstance.py", line 768, in _execute_task
    result = _execute_callable(context=context, **execute_callable_kwargs)
             ^^^^^^^^^^^^^^^^^^^^^^^^^^^^^^^^^^^^^^^^^^^^^^^^^^^^^^^^^^^^^
  File "/home/airflow/.local/lib/python3.12/site-packages/airflow/models/taskinstance.py", line 734, in _execute_callable
    return ExecutionCallableRunner(
           ^^^^^^^^^^^^^^^^^^^^^^^^
  File "/home/airflow/.local/lib/python3.12/site-packages/airflow/utils/operator_helpers.py", line 252, in run
    return self.func(*args, **kwargs)
           ^^^^^^^^^^^^^^^^^^^^^^^^^^
  File "/home/airflow/.local/lib/python3.12/site-packages/airflow/models/baseoperator.py", line 424, in wrapper
    return func(self, *args, **kwargs)
           ^^^^^^^^^^^^^^^^^^^^^^^^^^^
  File "/home/airflow/.local/lib/python3.12/site-packages/airflow/operators/python.py", line 238, in execute
    return_value = self.execute_callable()
                   ^^^^^^^^^^^^^^^^^^^^^^^
  File "/home/airflow/.local/lib/python3.12/site-packages/airflow/operators/python.py", line 256, in execute_callable
    return runner.run(*self.op_args, **self.op_kwargs)
           ^^^^^^^^^^^^^^^^^^^^^^^^^^^^^^^^^^^^^^^^^^^
  File "/home/airflow/.local/lib/python3.12/site-packages/airflow/utils/operator_helpers.py", line 252, in run
    return self.func(*args, **kwargs)
           ^^^^^^^^^^^^^^^^^^^^^^^^^^
  File "/opt/airflow/dags/scripts/S3_transformation_redshift.py", line 104, in process_and_load_data
    cursor.execute(copy_query)
psycopg2.errors.InternalError_: Spectrum Scan Error
DETAIL:  
  -----------------------------------------------
  error:  Spectrum Scan Error
  code:      15007
  context:   Unmatched number of columns between table and file. Table columns: 13, Data columns: 12, File name: https://s3.us-east-1.amazonaws.com/dataingestionjson/processed/2025-02-28/transformed_data.parquet
  query:     21826
  location:  dory_util.cpp:1758
  process:   worker_thread [pid=25433]
  -----------------------------------------------


[2025-03-01T15:21:18.152+0000] {local_task_job_runner.py:266} INFO - Task exited with return code 1
[2025-03-01T15:21:18.169+0000] {taskinstance.py:3901} INFO - 0 downstream tasks scheduled from follow-on schedule check
[2025-03-01T15:21:18.171+0000] {local_task_job_runner.py:245} INFO - ::endgroup::
