[2025-03-03T02:48:29.941+0000] {local_task_job_runner.py:123} INFO - ::group::Pre task execution logs
[2025-03-03T02:48:29.968+0000] {taskinstance.py:2614} INFO - Dependencies all met for dep_context=non-requeueable deps ti=<TaskInstance: s3_to_redshift_transformed.run_etl_task scheduled__2025-03-02T00:00:00+00:00 [queued]>
[2025-03-03T02:48:29.982+0000] {taskinstance.py:2614} INFO - Dependencies all met for dep_context=requeueable deps ti=<TaskInstance: s3_to_redshift_transformed.run_etl_task scheduled__2025-03-02T00:00:00+00:00 [queued]>
[2025-03-03T02:48:29.983+0000] {taskinstance.py:2867} INFO - Starting attempt 1 of 2
[2025-03-03T02:48:30.005+0000] {taskinstance.py:2890} INFO - Executing <Task(PythonOperator): run_etl_task> on 2025-03-02 00:00:00+00:00
[2025-03-03T02:48:30.016+0000] {logging_mixin.py:190} WARNING - /home/***/.local/lib/python3.12/site-packages/***/task/task_runner/standard_task_runner.py:70 DeprecationWarning: This process (pid=193) is multi-threaded, use of fork() may lead to deadlocks in the child.
[2025-03-03T02:48:30.019+0000] {standard_task_runner.py:72} INFO - Started process 219 to run task
[2025-03-03T02:48:30.017+0000] {standard_task_runner.py:104} INFO - Running: ['***', 'tasks', 'run', 's3_to_redshift_transformed', 'run_etl_task', 'scheduled__2025-03-02T00:00:00+00:00', '--job-id', '189', '--raw', '--subdir', 'DAGS_FOLDER/s3_transformation_redshift_dag.py', '--cfg-path', '/tmp/tmpo9nlj71a']
[2025-03-03T02:48:30.021+0000] {standard_task_runner.py:105} INFO - Job 189: Subtask run_etl_task
[2025-03-03T02:48:30.046+0000] {logging_mixin.py:190} WARNING - /home/***/.local/lib/python3.12/site-packages/***/settings.py:209 DeprecationWarning: The sql_alchemy_conn option in [core] has been moved to the sql_alchemy_conn option in [database] - the old setting has been used, but please update your config.
[2025-03-03T02:48:30.103+0000] {task_command.py:467} INFO - Running <TaskInstance: s3_to_redshift_transformed.run_etl_task scheduled__2025-03-02T00:00:00+00:00 [running]> on host 22871c84ed32
[2025-03-03T02:48:30.107+0000] {logging_mixin.py:190} WARNING - /home/***/.local/lib/python3.12/site-packages/***/settings.py:470 DeprecationWarning: The sql_alchemy_conn option in [core] has been moved to the sql_alchemy_conn option in [database] - the old setting has been used, but please update your config.
[2025-03-03T02:48:30.269+0000] {taskinstance.py:3134} INFO - Exporting env vars: AIRFLOW_CTX_DAG_OWNER='***' AIRFLOW_CTX_DAG_ID='s3_to_redshift_transformed' AIRFLOW_CTX_TASK_ID='run_etl_task' AIRFLOW_CTX_EXECUTION_DATE='2025-03-02T00:00:00+00:00' AIRFLOW_CTX_TRY_NUMBER='1' AIRFLOW_CTX_DAG_RUN_ID='scheduled__2025-03-02T00:00:00+00:00'
[2025-03-03T02:48:30.271+0000] {taskinstance.py:732} INFO - ::endgroup::
[2025-03-03T02:48:31.091+0000] {taskinstance.py:3313} ERROR - Task failed with exception
Traceback (most recent call last):
  File "/home/airflow/.local/lib/python3.12/site-packages/airflow/models/taskinstance.py", line 768, in _execute_task
    result = _execute_callable(context=context, **execute_callable_kwargs)
             ^^^^^^^^^^^^^^^^^^^^^^^^^^^^^^^^^^^^^^^^^^^^^^^^^^^^^^^^^^^^^
  File "/home/airflow/.local/lib/python3.12/site-packages/airflow/models/taskinstance.py", line 734, in _execute_callable
    return ExecutionCallableRunner(
           ^^^^^^^^^^^^^^^^^^^^^^^^
  File "/home/airflow/.local/lib/python3.12/site-packages/airflow/utils/operator_helpers.py", line 252, in run
    return self.func(*args, **kwargs)
           ^^^^^^^^^^^^^^^^^^^^^^^^^^
  File "/home/airflow/.local/lib/python3.12/site-packages/airflow/models/baseoperator.py", line 424, in wrapper
    return func(self, *args, **kwargs)
           ^^^^^^^^^^^^^^^^^^^^^^^^^^^
  File "/home/airflow/.local/lib/python3.12/site-packages/airflow/operators/python.py", line 238, in execute
    return_value = self.execute_callable()
                   ^^^^^^^^^^^^^^^^^^^^^^^
  File "/home/airflow/.local/lib/python3.12/site-packages/airflow/operators/python.py", line 256, in execute_callable
    return runner.run(*self.op_args, **self.op_kwargs)
           ^^^^^^^^^^^^^^^^^^^^^^^^^^^^^^^^^^^^^^^^^^^
  File "/home/airflow/.local/lib/python3.12/site-packages/airflow/utils/operator_helpers.py", line 252, in run
    return self.func(*args, **kwargs)
           ^^^^^^^^^^^^^^^^^^^^^^^^^^
  File "/opt/airflow/dags/scripts/S3_transformation_redshift.py", line 45, in process_and_load_data
    latest_ingestion_date = get_latest_partition(s3_bucket, s3_prefix)
                            ^^^^^^^^^^^^^^^^^^^^^^^^^^^^^^^^^^^^^^^^^^
  File "/opt/airflow/dags/scripts/S3_transformation_redshift.py", line 26, in get_latest_partition
    raise ValueError(f"No partitions found under s3://{bucket}/{prefix}")
ValueError: No partitions found under s3://dataingestionjson/users_events/
[2025-03-03T02:48:31.108+0000] {taskinstance.py:1226} INFO - Marking task as UP_FOR_RETRY. dag_id=s3_to_redshift_transformed, task_id=run_etl_task, run_id=scheduled__2025-03-02T00:00:00+00:00, execution_date=20250302T000000, start_date=20250303T024829, end_date=20250303T024831
[2025-03-03T02:48:31.139+0000] {taskinstance.py:341} INFO - ::group::Post task execution logs
[2025-03-03T02:48:31.140+0000] {standard_task_runner.py:124} ERROR - Failed to execute job 189 for task run_etl_task (No partitions found under s3://dataingestionjson/users_events/; 219)
Traceback (most recent call last):
  File "/home/airflow/.local/lib/python3.12/site-packages/airflow/task/task_runner/standard_task_runner.py", line 117, in _start_by_fork
    ret = args.func(args, dag=self.dag)
          ^^^^^^^^^^^^^^^^^^^^^^^^^^^^^
  File "/home/airflow/.local/lib/python3.12/site-packages/airflow/cli/cli_config.py", line 49, in command
    return func(*args, **kwargs)
           ^^^^^^^^^^^^^^^^^^^^^
  File "/home/airflow/.local/lib/python3.12/site-packages/airflow/utils/cli.py", line 116, in wrapper
    return f(*args, **kwargs)
           ^^^^^^^^^^^^^^^^^^
  File "/home/airflow/.local/lib/python3.12/site-packages/airflow/cli/commands/task_command.py", line 483, in task_run
    task_return_code = _run_task_by_selected_method(args, _dag, ti)
                       ^^^^^^^^^^^^^^^^^^^^^^^^^^^^^^^^^^^^^^^^^^^^
  File "/home/airflow/.local/lib/python3.12/site-packages/airflow/cli/commands/task_command.py", line 256, in _run_task_by_selected_method
    return _run_raw_task(args, ti)
           ^^^^^^^^^^^^^^^^^^^^^^^
  File "/home/airflow/.local/lib/python3.12/site-packages/airflow/cli/commands/task_command.py", line 341, in _run_raw_task
    return ti._run_raw_task(
           ^^^^^^^^^^^^^^^^^
  File "/home/airflow/.local/lib/python3.12/site-packages/airflow/utils/session.py", line 97, in wrapper
    return func(*args, session=session, **kwargs)
           ^^^^^^^^^^^^^^^^^^^^^^^^^^^^^^^^^^^^^^
  File "/home/airflow/.local/lib/python3.12/site-packages/airflow/models/taskinstance.py", line 3006, in _run_raw_task
    return _run_raw_task(
           ^^^^^^^^^^^^^^
  File "/home/airflow/.local/lib/python3.12/site-packages/airflow/models/taskinstance.py", line 274, in _run_raw_task
    TaskInstance._execute_task_with_callbacks(
  File "/home/airflow/.local/lib/python3.12/site-packages/airflow/models/taskinstance.py", line 3161, in _execute_task_with_callbacks
    result = self._execute_task(context, task_orig)
             ^^^^^^^^^^^^^^^^^^^^^^^^^^^^^^^^^^^^^^
  File "/home/airflow/.local/lib/python3.12/site-packages/airflow/models/taskinstance.py", line 3185, in _execute_task
    return _execute_task(self, context, task_orig)
           ^^^^^^^^^^^^^^^^^^^^^^^^^^^^^^^^^^^^^^^
  File "/home/airflow/.local/lib/python3.12/site-packages/airflow/models/taskinstance.py", line 768, in _execute_task
    result = _execute_callable(context=context, **execute_callable_kwargs)
             ^^^^^^^^^^^^^^^^^^^^^^^^^^^^^^^^^^^^^^^^^^^^^^^^^^^^^^^^^^^^^
  File "/home/airflow/.local/lib/python3.12/site-packages/airflow/models/taskinstance.py", line 734, in _execute_callable
    return ExecutionCallableRunner(
           ^^^^^^^^^^^^^^^^^^^^^^^^
  File "/home/airflow/.local/lib/python3.12/site-packages/airflow/utils/operator_helpers.py", line 252, in run
    return self.func(*args, **kwargs)
           ^^^^^^^^^^^^^^^^^^^^^^^^^^
  File "/home/airflow/.local/lib/python3.12/site-packages/airflow/models/baseoperator.py", line 424, in wrapper
    return func(self, *args, **kwargs)
           ^^^^^^^^^^^^^^^^^^^^^^^^^^^
  File "/home/airflow/.local/lib/python3.12/site-packages/airflow/operators/python.py", line 238, in execute
    return_value = self.execute_callable()
                   ^^^^^^^^^^^^^^^^^^^^^^^
  File "/home/airflow/.local/lib/python3.12/site-packages/airflow/operators/python.py", line 256, in execute_callable
    return runner.run(*self.op_args, **self.op_kwargs)
           ^^^^^^^^^^^^^^^^^^^^^^^^^^^^^^^^^^^^^^^^^^^
  File "/home/airflow/.local/lib/python3.12/site-packages/airflow/utils/operator_helpers.py", line 252, in run
    return self.func(*args, **kwargs)
           ^^^^^^^^^^^^^^^^^^^^^^^^^^
  File "/opt/airflow/dags/scripts/S3_transformation_redshift.py", line 45, in process_and_load_data
    latest_ingestion_date = get_latest_partition(s3_bucket, s3_prefix)
                            ^^^^^^^^^^^^^^^^^^^^^^^^^^^^^^^^^^^^^^^^^^
  File "/opt/airflow/dags/scripts/S3_transformation_redshift.py", line 26, in get_latest_partition
    raise ValueError(f"No partitions found under s3://{bucket}/{prefix}")
ValueError: No partitions found under s3://dataingestionjson/users_events/
[2025-03-03T02:48:31.187+0000] {local_task_job_runner.py:266} INFO - Task exited with return code 1
[2025-03-03T02:48:31.213+0000] {taskinstance.py:3901} INFO - 0 downstream tasks scheduled from follow-on schedule check
[2025-03-03T02:48:31.215+0000] {local_task_job_runner.py:245} INFO - ::endgroup::
